INFO:django.utils.autoreload:Watching for file changes with StatReloader
ERROR:django.request:Internal Server Error: /herosearch
Traceback (most recent call last):
  File "/home/jstrickler/.local/lib/python3.8/site-packages/django/core/handlers/exception.py", line 47, in inner
    response = get_response(request)
  File "/home/jstrickler/.local/lib/python3.8/site-packages/django/core/handlers/base.py", line 188, in _get_response
    self.check_response(response, callback)
  File "/home/jstrickler/.local/lib/python3.8/site-packages/django/core/handlers/base.py", line 309, in check_response
    raise ValueError(
ValueError: The view superheroes.views.herosearch didn't return an HttpResponse object. It returned None instead.
INFO:django.utils.autoreload:/home/jstrickler/Desktop/20210322django/EXAMPLES/DJANGO/djform/superheroes/views.py changed, reloading.
INFO:django.utils.autoreload:Watching for file changes with StatReloader
INFO:django.utils.autoreload:/home/jstrickler/Desktop/20210322django/EXAMPLES/DJANGO/djform/superheroes/views.py changed, reloading.
INFO:django.utils.autoreload:Watching for file changes with StatReloader
ERROR:django.request:Internal Server Error: /herosearch
Traceback (most recent call last):
  File "/home/jstrickler/.local/lib/python3.8/site-packages/django/core/handlers/exception.py", line 47, in inner
    response = get_response(request)
  File "/home/jstrickler/.local/lib/python3.8/site-packages/django/core/handlers/base.py", line 188, in _get_response
    self.check_response(response, callback)
  File "/home/jstrickler/.local/lib/python3.8/site-packages/django/core/handlers/base.py", line 309, in check_response
    raise ValueError(
ValueError: The view superheroes.views.herosearch didn't return an HttpResponse object. It returned None instead.
INFO:django.utils.autoreload:/home/jstrickler/Desktop/20210322django/EXAMPLES/DJANGO/djform/superheroes/views.py changed, reloading.
INFO:django.utils.autoreload:Watching for file changes with StatReloader
ERROR:django.request:Internal Server Error: /herosearch
Traceback (most recent call last):
  File "/home/jstrickler/.local/lib/python3.8/site-packages/django/core/handlers/exception.py", line 47, in inner
    response = get_response(request)
  File "/home/jstrickler/.local/lib/python3.8/site-packages/django/core/handlers/base.py", line 188, in _get_response
    self.check_response(response, callback)
  File "/home/jstrickler/.local/lib/python3.8/site-packages/django/core/handlers/base.py", line 309, in check_response
    raise ValueError(
ValueError: The view superheroes.views.herosearch didn't return an HttpResponse object. It returned None instead.
INFO:django.utils.autoreload:/home/jstrickler/Desktop/20210322django/EXAMPLES/DJANGO/djform/superheroes/views.py changed, reloading.
INFO:django.utils.autoreload:Watching for file changes with StatReloader
INFO:root:Created superhero Green Lantern
ERROR:django.request:Internal Server Error: /heroadd
Traceback (most recent call last):
  File "/home/jstrickler/.local/lib/python3.8/site-packages/django/db/models/fields/__init__.py", line 1774, in get_prep_value
    return int(value)
TypeError: int() argument must be a string, a bytes-like object or a number, not 'City'

The above exception was the direct cause of the following exception:

Traceback (most recent call last):
  File "/home/jstrickler/.local/lib/python3.8/site-packages/django/core/handlers/exception.py", line 47, in inner
    response = get_response(request)
  File "/home/jstrickler/.local/lib/python3.8/site-packages/django/core/handlers/base.py", line 181, in _get_response
    response = wrapped_callback(request, *callback_args, **callback_kwargs)
  File "/home/jstrickler/Desktop/20210322django/EXAMPLES/DJANGO/djform/superheroes/views.py", line 105, in heroadd
    hero.save()
  File "/home/jstrickler/Desktop/20210322django/EXAMPLES/DJANGO/djform/superheroes/models.py", line 75, in save
    super().save(*args, **kwargs)
  File "/home/jstrickler/.local/lib/python3.8/site-packages/django/db/models/base.py", line 753, in save
    self.save_base(using=using, force_insert=force_insert,
  File "/home/jstrickler/.local/lib/python3.8/site-packages/django/db/models/base.py", line 790, in save_base
    updated = self._save_table(
  File "/home/jstrickler/.local/lib/python3.8/site-packages/django/db/models/base.py", line 895, in _save_table
    results = self._do_insert(cls._base_manager, using, fields, returning_fields, raw)
  File "/home/jstrickler/.local/lib/python3.8/site-packages/django/db/models/base.py", line 933, in _do_insert
    return manager._insert(
  File "/home/jstrickler/.local/lib/python3.8/site-packages/django/db/models/manager.py", line 85, in manager_method
    return getattr(self.get_queryset(), name)(*args, **kwargs)
  File "/home/jstrickler/.local/lib/python3.8/site-packages/django/db/models/query.py", line 1254, in _insert
    return query.get_compiler(using=using).execute_sql(returning_fields)
  File "/home/jstrickler/.local/lib/python3.8/site-packages/django/db/models/sql/compiler.py", line 1396, in execute_sql
    for sql, params in self.as_sql():
  File "/home/jstrickler/.local/lib/python3.8/site-packages/django/db/models/sql/compiler.py", line 1339, in as_sql
    value_rows = [
  File "/home/jstrickler/.local/lib/python3.8/site-packages/django/db/models/sql/compiler.py", line 1340, in <listcomp>
    [self.prepare_value(field, self.pre_save_val(field, obj)) for field in fields]
  File "/home/jstrickler/.local/lib/python3.8/site-packages/django/db/models/sql/compiler.py", line 1340, in <listcomp>
    [self.prepare_value(field, self.pre_save_val(field, obj)) for field in fields]
  File "/home/jstrickler/.local/lib/python3.8/site-packages/django/db/models/sql/compiler.py", line 1281, in prepare_value
    value = field.get_db_prep_save(value, connection=self.connection)
  File "/home/jstrickler/.local/lib/python3.8/site-packages/django/db/models/fields/related.py", line 971, in get_db_prep_save
    return self.target_field.get_db_prep_save(value, connection=connection)
  File "/home/jstrickler/.local/lib/python3.8/site-packages/django/db/models/fields/__init__.py", line 823, in get_db_prep_save
    return self.get_db_prep_value(value, connection=connection, prepared=False)
  File "/home/jstrickler/.local/lib/python3.8/site-packages/django/db/models/fields/__init__.py", line 2388, in get_db_prep_value
    value = self.get_prep_value(value)
  File "/home/jstrickler/.local/lib/python3.8/site-packages/django/db/models/fields/__init__.py", line 1776, in get_prep_value
    raise e.__class__(
TypeError: Field 'id' expected a number but got <City: Metropolis>.
INFO:django.utils.autoreload:/home/jstrickler/Desktop/20210322django/EXAMPLES/DJANGO/djform/superheroes/views.py changed, reloading.
INFO:django.utils.autoreload:Watching for file changes with StatReloader
ERROR:django.request:Internal Server Error: /heroadd
Traceback (most recent call last):
  File "/home/jstrickler/.local/lib/python3.8/site-packages/django/core/handlers/exception.py", line 47, in inner
    response = get_response(request)
  File "/home/jstrickler/.local/lib/python3.8/site-packages/django/core/handlers/base.py", line 181, in _get_response
    response = wrapped_callback(request, *callback_args, **callback_kwargs)
  File "/home/jstrickler/Desktop/20210322django/EXAMPLES/DJANGO/djform/superheroes/views.py", line 106, in heroadd
    hero.city = city_id
  File "/home/jstrickler/.local/lib/python3.8/site-packages/django/db/models/fields/related_descriptors.py", line 215, in __set__
    raise ValueError(
ValueError: Cannot assign "'5'": "Superhero.city" must be a "City" instance.
INFO:django.utils.autoreload:/home/jstrickler/Desktop/20210322django/EXAMPLES/DJANGO/djform/superheroes/views.py changed, reloading.
INFO:django.utils.autoreload:Watching for file changes with StatReloader
ERROR:django.request:Internal Server Error: /heroadd
Traceback (most recent call last):
  File "/home/jstrickler/.local/lib/python3.8/site-packages/django/core/handlers/exception.py", line 47, in inner
    response = get_response(request)
  File "/home/jstrickler/.local/lib/python3.8/site-packages/django/core/handlers/base.py", line 181, in _get_response
    response = wrapped_callback(request, *callback_args, **callback_kwargs)
  File "/home/jstrickler/Desktop/20210322django/EXAMPLES/DJANGO/djform/superheroes/views.py", line 105, in heroadd
    hero.city = form.data.get('city')
  File "/home/jstrickler/.local/lib/python3.8/site-packages/django/db/models/fields/related_descriptors.py", line 215, in __set__
    raise ValueError(
ValueError: Cannot assign "'1'": "Superhero.city" must be a "City" instance.
ERROR:django.request:Internal Server Error: /heroadd
Traceback (most recent call last):
  File "/home/jstrickler/.local/lib/python3.8/site-packages/django/core/handlers/exception.py", line 47, in inner
    response = get_response(request)
  File "/home/jstrickler/.local/lib/python3.8/site-packages/django/core/handlers/base.py", line 181, in _get_response
    response = wrapped_callback(request, *callback_args, **callback_kwargs)
  File "/home/jstrickler/Desktop/20210322django/EXAMPLES/DJANGO/djform/superheroes/views.py", line 105, in heroadd
    hero.city = form.data.get('city')
  File "/home/jstrickler/.local/lib/python3.8/site-packages/django/db/models/fields/related_descriptors.py", line 215, in __set__
    raise ValueError(
ValueError: Cannot assign "'1'": "Superhero.city" must be a "City" instance.
INFO:django.utils.autoreload:/home/jstrickler/Desktop/20210322django/EXAMPLES/DJANGO/djform/superheroes/views.py changed, reloading.
INFO:django.utils.autoreload:Watching for file changes with StatReloader
WARNING:django.request:Not Found: /favicon.ico
ERROR:django.request:Internal Server Error: /heroadd
Traceback (most recent call last):
  File "/home/jstrickler/.local/lib/python3.8/site-packages/django/db/models/fields/__init__.py", line 1774, in get_prep_value
    return int(value)
TypeError: int() argument must be a string, a bytes-like object or a number, not 'City'

The above exception was the direct cause of the following exception:

Traceback (most recent call last):
  File "/home/jstrickler/.local/lib/python3.8/site-packages/django/core/handlers/exception.py", line 47, in inner
    response = get_response(request)
  File "/home/jstrickler/.local/lib/python3.8/site-packages/django/core/handlers/base.py", line 181, in _get_response
    response = wrapped_callback(request, *callback_args, **callback_kwargs)
  File "/home/jstrickler/Desktop/20210322django/EXAMPLES/DJANGO/djform/superheroes/views.py", line 105, in heroadd
    hero.city = City.objects.get(pk=city_id)
  File "/home/jstrickler/.local/lib/python3.8/site-packages/django/db/models/manager.py", line 85, in manager_method
    return getattr(self.get_queryset(), name)(*args, **kwargs)
  File "/home/jstrickler/.local/lib/python3.8/site-packages/django/db/models/query.py", line 418, in get
    clone = self._chain() if self.query.combinator else self.filter(*args, **kwargs)
  File "/home/jstrickler/.local/lib/python3.8/site-packages/django/db/models/query.py", line 942, in filter
    return self._filter_or_exclude(False, *args, **kwargs)
  File "/home/jstrickler/.local/lib/python3.8/site-packages/django/db/models/query.py", line 962, in _filter_or_exclude
    clone._filter_or_exclude_inplace(negate, *args, **kwargs)
  File "/home/jstrickler/.local/lib/python3.8/site-packages/django/db/models/query.py", line 969, in _filter_or_exclude_inplace
    self._query.add_q(Q(*args, **kwargs))
  File "/home/jstrickler/.local/lib/python3.8/site-packages/django/db/models/sql/query.py", line 1358, in add_q
    clause, _ = self._add_q(q_object, self.used_aliases)
  File "/home/jstrickler/.local/lib/python3.8/site-packages/django/db/models/sql/query.py", line 1377, in _add_q
    child_clause, needed_inner = self.build_filter(
  File "/home/jstrickler/.local/lib/python3.8/site-packages/django/db/models/sql/query.py", line 1319, in build_filter
    condition = self.build_lookup(lookups, col, value)
  File "/home/jstrickler/.local/lib/python3.8/site-packages/django/db/models/sql/query.py", line 1165, in build_lookup
    lookup = lookup_class(lhs, rhs)
  File "/home/jstrickler/.local/lib/python3.8/site-packages/django/db/models/lookups.py", line 24, in __init__
    self.rhs = self.get_prep_lookup()
  File "/home/jstrickler/.local/lib/python3.8/site-packages/django/db/models/lookups.py", line 76, in get_prep_lookup
    return self.lhs.output_field.get_prep_value(self.rhs)
  File "/home/jstrickler/.local/lib/python3.8/site-packages/django/db/models/fields/__init__.py", line 1776, in get_prep_value
    raise e.__class__(
TypeError: Field 'id' expected a number but got <City: Gateway City>.
INFO:django.utils.autoreload:/home/jstrickler/Desktop/20210322django/EXAMPLES/DJANGO/djform/superheroes/views.py changed, reloading.
INFO:django.utils.autoreload:Watching for file changes with StatReloader
INFO:root:Created superhero a
INFO:root:Created superhero Hawkeye
